Workbook

Sheet Récapitulatif 2025
A1: ORMES A — RÉCAPITULATIF DES CHARGES 2025
A2: Site : ORMES A | Période : 01/01/2025 – 31/12/2025
A3: Fournisseur | B3: Date facture | C3: N° facture | D3: Description | E3: Montant HT (€) | F3: TVA (€) | G3: Montant TTC (€)
A4: ── FLUIDES ──
A5: Eau
A6: AQUALIGE | C6: 1096904376-1 | D6: Mise en service | E6: 49.82 | F6: 4.98 | G6: 54.8
A7: AQUALIGE | C7: 1096892743-1 | D7: Mise en service | E7: 49.82 | F7: 4.98 | G7: 54.8
A8: AQUALIGE | B8: 45854 | C8: 1099190061 | D8: EAU ET ASSAINISSEMENT COMPTEUR 124MK046246 | E8: 645.02 | F8: 46.22 | G8: 691.24
A9: AQUALIGE | B9: 45854 | C9: 1099203459 | D9: EAU ET ASSAINISSEMENT COMPTEUR C24FE015783 | E9: 292.74 | F9: 21.75 | G9: 314.49
A10: Sous-total — Eau | E10: =SUM(E6:E9) | F10: =SUM(F6:F9) | G10: =SUM(G6:G9)
A11: Electricité
A12: ENGIE | B12: 45780 | C12: 1200009625875 | D12: CONSOMMATIONS ELECTRICITE 01/04/2025 au 30/04/2025 | E12: 4337.28 | F12: 867.46 | G12: 5204.74
A13: ENGIE | B13: 45813 | C13: 40017044367 | D13: CONSOMMATIONS ELECTRICTITE | E13: 3646.51 | F13: 729.3 | G13: 4375.81
A14: ENGIE | B14: 45843 | C14: 520002087186 | D14: CONSOMMATIONS ELECTRICTITE | E14: 3379.85 | F14: 675.97 | G14: 4055.82
A15: ENGIE | B15: 45876 | C15: 320007792334 | D15: CONSOMMATIONS ELECTRICTITE | E15: 3600.2 | F15: 720.04 | G15: 4320.24
A16: ENGIE | B16: 45904 | C16: 760000335269 | D16: CONSOMMATIONS ELECTRICTITE | E16: 3715.72 | F16: 743.14 | G16: 4458.86
A17: ENGIE | B17: 45934 | C17: 630000369535 | D17: CONSOMMATIONS ELECTRICTITE | E17: 3737.12 | F17: 747.42 | G17: 4484.54
A18: ENGIE | B18: 45965 | C18: 690000378639 | D18: CONSOMMATIONS ELECTRICTITE | E18: 4184.89 | F18: 836.98 | G18: 5021.87
A19: ENGIE | B19: 45995 | C19: 670000394240 | D19: CONSOMMATIONS ELECTRICTITE | E19: 6650.18 | F19: 1330.04 | G19: 7980.22
A20: ENGIE | B20: 46025 | C20: 980006173374 | D20: CONSOMMATIONS ELECTRICTITE | E20: 7445.64 | F20: 1489.13 | G20: 8934.77
A21: Sous-total — Electricité | E21: =SUM(E12:E20) | F21: =SUM(F12:F20) | G21: =SUM(G12:G20)
A22: Gaz
A23: ENGIE | B23: 45782 | C23: 680000258800 | D23: CONSOMMATIONS GAZ 02/04/2025 au 01/05/2025 | E23: 2147.53 | F23: 160.14 | G23: 2307.67
A24: ENGIE | B24: 45813 | C24: 780000262507 | D24: CONSOMMATIONS GAZ | E24: 2039.74 | F24: 125.43 | G24: 2165.17
A25: ENGIE | B25: 45842 | C25: 820001240297 | D25: CONSOMMATIONS GAZ | E25: 2039.74 | F25: 125.43 | G25: 2165.17
A26: ENGIE | B26: 45873 | C26: 40017074775 | D26: CONSOMMATIONS GAZ | E26: 2048.67 | F26: 126.15 | G26: 2174.82
A27: ENGIE | B27: 45904 | C27: 65000032141 | D27: CONSOMMATIONS GAZ | E27: 2048.67 | F27: 409.73 | G27: 2458.4
A28: ENGIE | B28: 45934 | C28: 420006908243 | D28: CONSOMMATIONS GAZ | E28: 2048.67 | F28: 409.73 | G28: 2458.4
A29: ENGIE | B29: 45966 | C29: 690000380305 | D29: CONSOMMATIONS GAZ | E29: 2049.48 | F29: 409.9 | G29: 2459.38
A30: ENGIE | B30: 45995 | C30: 820006290113 | D30: CONSOMMATIONS GAZ | E30: 2055.74 | F30: 411.15 | G30: 2466.89
A31: ENGIE | B31: 46026 | C31: 20040377238 | D31: CONSOMMATIONS GAZ | E31: 2063.48 | F31: 412.7 | G31: 2476.18
A32: Sous-total — Gaz | E32: =SUM(E23:E31) | F32: =SUM(F23:F31) | G32: =SUM(G23:G31)
A33: ── TRAVAUX ──
A34: Entretien Courant
A35: ESPACE CLOTURE CENTRE | B35: 45803 | C35: 18011749 | D35: INSTALLATION BOUCLE SORTIE SUR PORTAIL VL | E35: 610 | F35: 122 | G35: 732
A36: ESPACE CLOTURE CENTRE | B36: 45832 | C36: 18011816 | D36: POSE DIGICODE | E36: 734.4 | F36: 146.88 | G36: 881.28
A37: Sous-total — Entretien Courant | E37: =SUM(E35:E36) | F37: =SUM(F35:F36) | G37: =SUM(G35:G36)
A38: ── CONTRAT MAINTENANCE ──
A39: Espaces Verts
A40: ARP ASTRANCE | B40: 45838 | C40: FC-ARP-25-06-0141 | D40: Suivis écologiques | E40: 1500 | F40: 300 | G40: 1800
...

Sheet Paramètres
A1: ORMES A — PARAMÈTRES SITE 2025
A2: Site | C2: ORMES A
A3: Surface totale site (m²) | C3: 29565.91
A4: Année | C4: 2025
A6: Lot | B6: Statut | C6: Surface (m²) | D6: Bâtiment | E6: Locataire | F6: Début de bail | G6: Fin de bail | H6: Jours 2025 | I6: Prorata
A7: C1 C2 | B7: Occupé | C7: 9623 | E7: ID LOGISTICS | F7: 45737 | G7: 50119 | H7: =MAX(0,MIN(DATE(2025,12,31),IF(G7="",DATE(2025,12,31),G7))-MAX(DATE(2025,1,1),IF(F7="",DATE(2025,1,1),F7))+1) | I7: =H7/365
A8: C3 C4 C5 | B8: Vacant | C8: 19942.91 | H8: =MAX(0,MIN(DATE(2025,12,31),IF(G8="",DATE(2025,12,31),G8))-MAX(DATE(2025,1,1),IF(F8="",DATE(2025,1,1),F8))+1) | I8: =H8/365
A10: Poste (lié au Récapitulatif) | C10: Montant HT (€)
A11: =IFERROR(MID('Récapitulatif 2025'!A10,FIND(" — ",'Récapitulatif 2025'!A10)+4,100),"") | C11: ='Récapitulatif 2025'!E10
A12: =IFERROR(MID('Récapitulatif 2025'!A21,FIND(" — ",'Récapitulatif 2025'!A21)+4,100),"") | C12: ='Récapitulatif 2025'!E21
A13: =IFERROR(MID('Récapitulatif 2025'!A32,FIND(" — ",'Récapitulatif 2025'!A32)+4,100),"") | C13: ='Récapitulatif 2025'!E32
A14: =IFERROR(MID('Récapitulatif 2025'!A37,FIND(" — ",'Récapitulatif 2025'!A37)+4,100),"") | C14: ='Récapitulatif 2025'!E37
A15: =IFERROR(MID('Récapitulatif 2025'!A46,FIND(" — ",'Récapitulatif 2025'!A46)+4,100),"") | C15: ='Récapitulatif 2025'!E46
A16: =IFERROR(MID('Récapitulatif 2025'!A50,FIND(" — ",'Récapitulatif 2025'!A50)+4,100),"") | C16: ='Récapitulatif 2025'!E50
A17: =IFERROR(MID('Récapitulatif 2025'!A54,FIND(" — ",'Récapitulatif 2025'!A54)+4,100),"") | C17: ='Récapitulatif 2025'!E54
A18: =IFERROR(MID('Récapitulatif 2025'!A59,FIND(" — ",'Récapitulatif 2025'!A59)+4,100),"") | C18: ='Récapitulatif 2025'!E59
A19: =IFERROR(MID('Récapitulatif 2025'!A64,FIND(" — ",'Récapitulatif 2025'!A64)+4,100),"") | C19: ='Récapitulatif 2025'!E64
A20: =IFERROR(MID('Récapitulatif 2025'!A77,FIND(" — ",'Récapitulatif 2025'!A77)+4,100),"") | C20: ='Récapitulatif 2025'!E77
A21: =IFERROR(MID('Récapitulatif 2025'!A83,FIND(" — ",'Récapitulatif 2025'!A83)+4,100),"") | C21: ='Récapitulatif 2025'!E83
A22: =IFERROR(MID('Récapitulatif 2025'!A88,FIND(" — ",'Récapitulatif 2025'!A88)+4,100),"") | C22: ='Récapitulatif 2025'!E88
A23: =IFERROR(MID('Récapitulatif 2025'!A97,FIND(" — ",'Récapitulatif 2025'!A97)+4,100),"") | C23: ='Récapitulatif 2025'!E97
A24: =IFERROR(MID('Récapitulatif 2025'!A101,FIND(" — ",'Récapitulatif 2025'!A101)+4,100),"") | C24: ='Récapitulatif 2025'!E101
A25: =IFERROR(MID('Récapitulatif 2025'!A104,FIND(" — ",'Récapitulatif 2025'!A104)+4,100),"") | C25: ='Récapitulatif 2025'!E104
A26: =IFERROR(MID('Récapitulatif 2025'!A107,FIND(" — ",'Récapitulatif 2025'!A107)+4,100),"") | C26: ='Récapitulatif 2025'!E107
A27: =IFERROR(MID('Récapitulatif 2025'!A111,FIND(" — ",'Récapitulatif 2025'!A111)+4,100),"") | C27: ='Récapitulatif 2025'!E111
A28: =IFERROR(MID('Récapitulatif 2025'!A118,FIND(" — ",'Récapitulatif 2025'!A118)+4,100),"") | C28: ='Récapitulatif 2025'!E118

Sheet C1 C2
A1: RÉGULARISATION DE CHARGES — C1 C2
A2: Site : ORMES A | Année 2025
A3: =Paramètres!$B$7&IF(Paramètres!$E$7<>""," — "&Paramètres!$E$7,"")
A4: Poste | B4: Clé répartition | C4: Total site HT | D4: QP annuelle | E4: Période | F4: QP locataire
A5: FLUIDES
A6: Eau | B6: =Paramètres!$C$7/Paramètres!$C$3 | C6: ='Récapitulatif 2025'!E10 | D6: =B6*C6 | E6: =Paramètres!$H$7/365 | F6: =D6*E6
A7: Electricité | B7: =Paramètres!$C$7/Paramètres!$C$3 | C7: ='Récapitulatif 2025'!E21 | D7: =B7*C7 | E7: =Paramètres!$H$7/365 | F7: =D7*E7
A8: Gaz | B8: =Paramètres!$C$7/Paramètres!$C$3 | C8: ='Récapitulatif 2025'!E32 | D8: =B8*C8 | E8: =Paramètres!$H$7/365 | F8: =D8*E8
A9: Sous-total — FLUIDES | C9: =SUM(C6:C8) | D9: =SUM(D6:D8) | F9: =SUM(F6:F8)
A10: TRAVAUX
A11: Entretien Courant | B11: =Paramètres!$C$7/Paramètres!$C$3 | C11: ='Récapitulatif 2025'!E37 | D11: =B11*C11 | E11: =Paramètres!$H$7/365 | F11: =D11*E11
A12: Sous-total — TRAVAUX | C12: =SUM(C11:C11) | D12: =SUM(D11:D11) | F12: =SUM(F11:F11)
A13: CONTRAT MAINTENANCE
A14: Espaces Verts | B14: =Paramètres!$C$7/Paramètres!$C$3 | C14: ='Récapitulatif 2025'!E46 | D14: =B14*C14 | E14: =Paramètres!$H$7/365 | F14: =D14*E14
A15: CVC | B15: =Paramètres!$C$7/Paramètres!$C$3 | C15: ='Récapitulatif 2025'!E50 | D15: =B15*C15 | E15: =Paramètres!$H$7/365 | F15: =D15*E15
A16: Sécurité | B16: =Paramètres!$C$7/Paramètres!$C$3 | C16: ='Récapitulatif 2025'!E54 | D16: =B16*C16 | E16: =Paramètres!$H$7/365 | F16: =D16*E16
A17: SSI | B17: =Paramètres!$C$7/Paramètres!$C$3 | C17: ='Récapitulatif 2025'!E59 | D17: =B17*C17 | E17: =Paramètres!$H$7/365 | F17: =D17*E17
A18: Toitures | B18: =Paramètres!$C$7/Paramètres!$C$3 | C18: ='Récapitulatif 2025'!E64 | D18: =B18*C18 | E18: =Paramètres!$H$7/365 | F18: =D18*E18
A19: SPK / RIA / PI | B19: =Paramètres!$C$7/Paramètres!$C$3 | C19: ='Récapitulatif 2025'!E77 | D19: =B19*C19 | E19: =Paramètres!$H$7/365 | F19: =D19*E19
A20: Installations électriques | B20: =Paramètres!$C$7/35730.0 | C20: ='Récapitulatif 2025'!E83 | D20: =B20*C20 | E20: =Paramètres!$H$7/365 | F20: =D20*E20
A21: Protection Foudre | B21: =Paramètres!$C$7/23820.0 | C21: ='Récapitulatif 2025'!E88 | D21: =B21*C21 | E21: =Paramètres!$H$7/365 | F21: =D21*E21
A22: GTB | B22: =Paramètres!$C$7/Paramètres!$C$3 | C22: ='Récapitulatif 2025'!E97 | D22: =B22*C22 | E22: =Paramètres!$H$7/365 | F22: =D22*E22
A23: Détection Gaz | B23: =Paramètres!$C$7/Paramètres!$C$3 | C23: ='Récapitulatif 2025'!E101 | D23: =B23*C23 | E23: =Paramètres!$H$7/365 | F23: =D23*E23
A24: Vérifications règlementaires | B24: =Paramètres!$C$7/19945.0 | C24: ='Récapitulatif 2025'!E104 | D24: =B24*C24 | E24: =Paramètres!$H$7/365 | F24: =D24*E24
A25: Portails | B25: =Paramètres!$C$7/Paramètres!$C$3 | C25: ='Récapitulatif 2025'!E107 | D25: =B25*C25 | E25: =Paramètres!$H$7/365 | F25: =D25*E25
A26: Sous-total — CONTRAT MAINTENANCE | C26: =SUM(C14:C25) | D26: =SUM(D14:D25) | F26: =SUM(F14:F25)
A27: ASSURANCES + JURIDIQUE
A28: Assurances | B28: =Paramètres!$C$7/Paramètres!$C$3 | C28: ='Récapitulatif 2025'!E111 | D28: =B28*C28 | E28: =Paramètres!$H$7/365 | F28: =D28*E28
A29: Sous-total — ASSURANCES + JURIDIQUE | C29: =SUM(C28:C28) | D29: =SUM(D28:D28) | F29: =SUM(F28:F28)
A31: HONORAIRES
A32: Honoraires Gestion Technique | E32: 1 | F32: =IF(D32="","",D32*E32)
A33: Sous-total — HONORAIRES | C33: =SUM(C32:C32) | D33: =SUM(D32:D32) | F33: =SUM(F32:F32)
A35: TOTAL CHARGES RÉCUPÉRABLES RÉELLES (€ HT) | C35: =C9+C12+C26+C29+C33 | D35: =D9+D12+D26+D29+D33 | F35: =F9+F12+F26+F29+F33
A37: Provisions pour charges versées | D37: Montant annuel (€) | F37: Montant locataire (€)
A38: 1er trimestre (T1) | F38: 2990.6
A39: 2e trimestre (T2) | F39: 25284.11
A40: 3e trimestre (T3) | F40: 28376.42
A41: 4e trimestre (T4) | F41: 28376.42
A42: Total provisions pour charges versées → | D42: =SUM(D38:D41) | F42: =SUM(F38:F41)
A44: =IF(F35-F42>0,"SOLDE DÉBITEUR","SOLDE CRÉDITEUR") | D44: =D35-D42 | F44: =F35-F42
...

Sheet C3 C4 C5
A1: RÉGULARISATION DE CHARGES — C3 C4 C5
A2: Site : ORMES A | Année 2025
A3: =Paramètres!$B$8&IF(Paramètres!$E$8<>""," — "&Paramètres!$E$8,"")
A4: Poste | B4: Clé répartition | C4: Total site HT | D4: QP annuelle | E4: Période | F4: QP locataire
A5: FLUIDES
A6: Eau | B6: =Paramètres!$C$8/Paramètres!$C$3 | C6: ='Récapitulatif 2025'!E10 | D6: =B6*C6 | E6: =Paramètres!$H$8/365 | F6: =D6*E6
A7: Electricité | B7: =Paramètres!$C$8/Paramètres!$C$3 | C7: ='Récapitulatif 2025'!E21 | D7: =B7*C7 | E7: =Paramètres!$H$8/365 | F7: =D7*E7
A8: Gaz | B8: =Paramètres!$C$8/Paramètres!$C$3 | C8: ='Récapitulatif 2025'!E32 | D8: =B8*C8 | E8: =Paramètres!$H$8/365 | F8: =D8*E8
A9: Sous-total — FLUIDES | C9: =SUM(C6:C8) | D9: =SUM(D6:D8) | F9: =SUM(F6:F8)
A10: TRAVAUX
A11: Entretien Courant | B11: =Paramètres!$C$8/Paramètres!$C$3 | C11: ='Récapitulatif 2025'!E37 | D11: =B11*C11 | E11: =Paramètres!$H$8/365 | F11: =D11*E11
A12: Sous-total — TRAVAUX | C12: =SUM(C11:C11) | D12: =SUM(D11:D11) | F12: =SUM(F11:F11)
A13: CONTRAT MAINTENANCE
A14: Espaces Verts | B14: =Paramètres!$C$8/Paramètres!$C$3 | C14: ='Récapitulatif 2025'!E46 | D14: =B14*C14 | E14: =Paramètres!$H$8/365 | F14: =D14*E14
A15: CVC | B15: =Paramètres!$C$8/Paramètres!$C$3 | C15: ='Récapitulatif 2025'!E50 | D15: =B15*C15 | E15: =Paramètres!$H$8/365 | F15: =D15*E15
A16: Sécurité | B16: =Paramètres!$C$8/Paramètres!$C$3 | C16: ='Récapitulatif 2025'!E54 | D16: =B16*C16 | E16: =Paramètres!$H$8/365 | F16: =D16*E16
A17: SSI | B17: =Paramètres!$C$8/Paramètres!$C$3 | C17: ='Récapitulatif 2025'!E59 | D17: =B17*C17 | E17: =Paramètres!$H$8/365 | F17: =D17*E17
A18: Toitures | B18: =Paramètres!$C$8/Paramètres!$C$3 | C18: ='Récapitulatif 2025'!E64 | D18: =B18*C18 | E18: =Paramètres!$H$8/365 | F18: =D18*E18
A19: SPK / RIA / PI | B19: =Paramètres!$C$8/Paramètres!$C$3 | C19: ='Récapitulatif 2025'!E77 | D19: =B19*C19 | E19: =Paramètres!$H$8/365 | F19: =D19*E19
A20: Installations électriques | B20: =Paramètres!$C$8/35730.0 | C20: ='Récapitulatif 2025'!E83 | D20: =B20*C20 | E20: =Paramètres!$H$8/365 | F20: =D20*E20
A21: Protection Foudre | B21: =Paramètres!$C$8/23820.0 | C21: ='Récapitulatif 2025'!E88 | D21: =B21*C21 | E21: =Paramètres!$H$8/365 | F21: =D21*E21
A22: GTB | B22: =Paramètres!$C$8/Paramètres!$C$3 | C22: ='Récapitulatif 2025'!E97 | D22: =B22*C22 | E22: =Paramètres!$H$8/365 | F22: =D22*E22
A23: Détection Gaz | B23: =Paramètres!$C$8/Paramètres!$C$3 | C23: ='Récapitulatif 2025'!E101 | D23: =B23*C23 | E23: =Paramètres!$H$8/365 | F23: =D23*E23
A24: Vérifications règlementaires | B24: =Paramètres!$C$8/19945.0 | C24: ='Récapitulatif 2025'!E104 | D24: =B24*C24 | E24: =Paramètres!$H$8/365 | F24: =D24*E24
A25: Portails | B25: =Paramètres!$C$8/Paramètres!$C$3 | C25: ='Récapitulatif 2025'!E107 | D25: =B25*C25 | E25: =Paramètres!$H$8/365 | F25: =D25*E25
A26: Sous-total — CONTRAT MAINTENANCE | C26: =SUM(C14:C25) | D26: =SUM(D14:D25) | F26: =SUM(F14:F25)
A27: ASSURANCES + JURIDIQUE
A28: Assurances | B28: =Paramètres!$C$8/Paramètres!$C$3 | C28: ='Récapitulatif 2025'!E111 | D28: =B28*C28 | E28: =Paramètres!$H$8/365 | F28: =D28*E28
A29: Sous-total — ASSURANCES + JURIDIQUE | C29: =SUM(C28:C28) | D29: =SUM(D28:D28) | F29: =SUM(F28:F28)
A31: HONORAIRES
A32: Honoraires Gestion Technique | E32: 1 | F32: =IF(D32="","",D32*E32)
A33: Sous-total — HONORAIRES | C33: =SUM(C32:C32) | D33: =SUM(D32:D32) | F33: =SUM(F32:F32)
A35: TOTAL CHARGES RÉCUPÉRABLES RÉELLES (€ HT) | C35: =C9+C12+C26+C29+C33 | D35: =D9+D12+D26+D29+D33 | F35: =F9+F12+F26+F29+F33
A37: Provisions pour charges versées | D37: Montant annuel (€) | F37: Montant locataire (€)
A38: 1er trimestre (T1)
A39: 2e trimestre (T2)
A40: 3e trimestre (T3)
A41: 4e trimestre (T4)
A42: Total provisions pour charges versées → | D42: =SUM(D38:D41) | F42: =SUM(F38:F41)
A44: =IF(F35-F42>0,"SOLDE DÉBITEUR","SOLDE CRÉDITEUR") | D44: =D35-D42 | F44: =F35-F42
...

Sheet Vacance Locative
A1: ORMES A — COÛT DE LA VACANCE LOCATIVE 2025
A2: Estimation de la perte de charges non récupérées sur les lots vacants
A4: Lot | B4: Statut | C4: Surface (m²) | D4: QP annuelle (€ HT) | E4: Période (j/365) | F4: Coût vacance (€ HT)
A5: =Paramètres!A7 | B5: =Paramètres!B7 | C5: =Paramètres!C7 | D5: ='C1 C2'!D35 | E5: =Paramètres!H7/365 | F5: =IF(Paramètres!B7="Vacant",'C1 C2'!D35,'C1 C2'!D35-'C1 C2'!F35)
A6: =Paramètres!A8 | B6: =Paramètres!B8 | C6: =Paramètres!C8 | D6: ='C3 C4 C5'!D35 | E6: =Paramètres!H8/365 | F6: =IF(Paramètres!B8="Vacant",'C3 C4 C5'!D35,'C3 C4 C5'!D35-'C3 C4 C5'!F35)
A8: Total QP charges (tous lots) | D8: =SUM(D5:D6)
A9: Nombre de lots vacants | D9: =COUNTIF(B5:B6,"Vacant")
A11: Charges non récupérables (Frais Bancaires + CAPEX) | F11: ='Récapitulatif 2025'!E118
A13: TOTAL COÛT DE LA VACANCE LOCATIVE (€ HT) | F13: =F5+F6+F11
A15: Part vacance sur total charges site | F15: =IF(D8>0,F13/D8,0)
A17: ℹ QP annuelle = Total site HT × clé de répartition. Coût vacance = QP annuelle × fraction de l'année non occupée.
